Traceback (most recent call last):
  File "/Users/adamaiken/opt/anaconda3/lib/python3.9/site-packages/jupyter_cache/executors/utils.py", line 51, in single_nb_execution
    executenb(
  File "/Users/adamaiken/opt/anaconda3/lib/python3.9/site-packages/nbclient/client.py", line 1112, in execute
    return NotebookClient(nb=nb, resources=resources, km=km, **kwargs).execute()
  File "/Users/adamaiken/opt/anaconda3/lib/python3.9/site-packages/nbclient/util.py", line 74, in wrapped
    return just_run(coro(*args, **kwargs))
  File "/Users/adamaiken/opt/anaconda3/lib/python3.9/site-packages/nbclient/util.py", line 53, in just_run
    return loop.run_until_complete(coro)
  File "/Users/adamaiken/opt/anaconda3/lib/python3.9/asyncio/base_events.py", line 642, in run_until_complete
    return future.result()
  File "/Users/adamaiken/opt/anaconda3/lib/python3.9/site-packages/nbclient/client.py", line 553, in async_execute
    await self.async_execute_cell(
  File "/Users/adamaiken/opt/anaconda3/lib/python3.9/site-packages/nbclient/client.py", line 857, in async_execute_cell
    self._check_raise_for_error(cell, exec_reply)
  File "/Users/adamaiken/opt/anaconda3/lib/python3.9/site-packages/nbclient/client.py", line 760, in _check_raise_for_error
    raise CellExecutionError.from_cell_and_msg(cell, exec_reply_content)
nbclient.exceptions.CellExecutionError: An error occurred while executing the following cell:
------------------
data = nasdaqdatalink.get("FRED/GDP", start_date="1999-12-31", end_date="2021-12-31")

type(data)
------------------

[0;31m---------------------------------------------------------------------------[0m
[0;31mDataLinkError[0m                             Traceback (most recent call last)
[0;32m/var/folders/sm/f4lq92s11392x68kwf0scq3w0000gn/T/ipykernel_44360/1894021087.py[0m in [0;36m<module>[0;34m[0m
[0;32m----> 1[0;31m [0mdata[0m [0;34m=[0m [0mnasdaqdatalink[0m[0;34m.[0m[0mget[0m[0;34m([0m[0;34m"FRED/GDP"[0m[0;34m,[0m [0mstart_date[0m[0;34m=[0m[0;34m"1999-12-31"[0m[0;34m,[0m [0mend_date[0m[0;34m=[0m[0;34m"2021-12-31"[0m[0;34m)[0m[0;34m[0m[0;34m[0m[0m
[0m[1;32m      2[0m [0;34m[0m[0m
[1;32m      3[0m [0mtype[0m[0;34m([0m[0mdata[0m[0;34m)[0m[0;34m[0m[0;34m[0m[0m

[0;32m~/opt/anaconda3/lib/python3.9/site-packages/nasdaqdatalink/get.py[0m in [0;36mget[0;34m(dataset, **kwargs)[0m
[1;32m     46[0m         [0;32mif[0m [0mdataset_args[0m[0;34m[[0m[0;34m'column_index'[0m[0;34m][0m [0;32mis[0m [0;32mnot[0m [0;32mNone[0m[0;34m:[0m[0;34m[0m[0;34m[0m[0m
[1;32m     47[0m             [0mkwargs[0m[0;34m.[0m[0mupdate[0m[0;34m([0m[0;34m{[0m[0;34m'column_index'[0m[0;34m:[0m [0mdataset_args[0m[0;34m[[0m[0;34m'column_index'[0m[0;34m][0m[0;34m}[0m[0;34m)[0m[0;34m[0m[0;34m[0m[0m
[0;32m---> 48[0;31m         [0mdata[0m [0;34m=[0m [0mDataset[0m[0;34m([0m[0mdataset_args[0m[0;34m[[0m[0;34m'code'[0m[0;34m][0m[0;34m)[0m[0;34m.[0m[0mdata[0m[0;34m([0m[0mparams[0m[0;34m=[0m[0mkwargs[0m[0;34m,[0m [0mhandle_column_not_found[0m[0;34m=[0m[0;32mTrue[0m[0;34m)[0m[0;34m[0m[0;34m[0m[0m
[0m[1;32m     49[0m     [0;31m# Array[0m[0;34m[0m[0;34m[0m[0m
[1;32m     50[0m     [0;32melif[0m [0misinstance[0m[0;34m([0m[0mdataset[0m[0;34m,[0m [0mlist[0m[0;34m)[0m[0;34m:[0m[0;34m[0m[0;34m[0m[0m

[0;32m~/opt/anaconda3/lib/python3.9/site-packages/nasdaqdatalink/model/dataset.py[0m in [0;36mdata[0;34m(self, **options)[0m
[1;32m     45[0m         [0mupdated_options[0m [0;34m=[0m [0mUtil[0m[0;34m.[0m[0mmerge_options[0m[0;34m([0m[0;34m'params'[0m[0;34m,[0m [0mparams[0m[0;34m,[0m [0;34m**[0m[0moptions[0m[0;34m)[0m[0;34m[0m[0;34m[0m[0m
[1;32m     46[0m         [0;32mtry[0m[0;34m:[0m[0;34m[0m[0;34m[0m[0m
[0;32m---> 47[0;31m             [0;32mreturn[0m [0mData[0m[0;34m.[0m[0mall[0m[0;34m([0m[0;34m**[0m[0mupdated_options[0m[0;34m)[0m[0;34m[0m[0;34m[0m[0m
[0m[1;32m     48[0m         [0;32mexcept[0m [0mNotFoundError[0m[0;34m:[0m[0;34m[0m[0;34m[0m[0m
[1;32m     49[0m             [0;32mif[0m [0mhandle_not_found_error[0m[0;34m:[0m[0;34m[0m[0;34m[0m[0m

[0;32m~/opt/anaconda3/lib/python3.9/site-packages/nasdaqdatalink/operations/list.py[0m in [0;36mall[0;34m(cls, **options)[0m
[1;32m     13[0m             [0moptions[0m[0;34m[[0m[0;34m'params'[0m[0;34m][0m [0;34m=[0m [0;34m{[0m[0;34m}[0m[0;34m[0m[0;34m[0m[0m
[1;32m     14[0m         [0mpath[0m [0;34m=[0m [0mUtil[0m[0;34m.[0m[0mconstructed_path[0m[0;34m([0m[0mcls[0m[0;34m.[0m[0mlist_path[0m[0;34m([0m[0;34m)[0m[0;34m,[0m [0moptions[0m[0;34m[[0m[0;34m'params'[0m[0;34m][0m[0;34m)[0m[0;34m[0m[0;34m[0m[0m
[0;32m---> 15[0;31m         [0mr[0m [0;34m=[0m [0mConnection[0m[0;34m.[0m[0mrequest[0m[0;34m([0m[0;34m'get'[0m[0;34m,[0m [0mpath[0m[0;34m,[0m [0;34m**[0m[0moptions[0m[0;34m)[0m[0;34m[0m[0;34m[0m[0m
[0m[1;32m     16[0m         [0mresponse_data[0m [0;34m=[0m [0mr[0m[0;34m.[0m[0mjson[0m[0;34m([0m[0;34m)[0m[0;34m[0m[0;34m[0m[0m
[1;32m     17[0m         [0mUtil[0m[0;34m.[0m[0mconvert_to_dates[0m[0;34m([0m[0mresponse_data[0m[0;34m)[0m[0;34m[0m[0;34m[0m[0m

[0;32m~/opt/anaconda3/lib/python3.9/site-packages/nasdaqdatalink/connection.py[0m in [0;36mrequest[0;34m(cls, http_verb, url, **options)[0m
[1;32m     37[0m         [0mabs_url[0m [0;34m=[0m [0;34m'%s/%s'[0m [0;34m%[0m [0;34m([0m[0mApiConfig[0m[0;34m.[0m[0mapi_base[0m[0;34m,[0m [0murl[0m[0;34m)[0m[0;34m[0m[0;34m[0m[0m
[1;32m     38[0m [0;34m[0m[0m
[0;32m---> 39[0;31m         [0;32mreturn[0m [0mcls[0m[0;34m.[0m[0mexecute_request[0m[0;34m([0m[0mhttp_verb[0m[0;34m,[0m [0mabs_url[0m[0;34m,[0m [0;34m**[0m[0moptions[0m[0;34m)[0m[0;34m[0m[0;34m[0m[0m
[0m[1;32m     40[0m [0;34m[0m[0m
[1;32m     41[0m     [0;34m@[0m[0mclassmethod[0m[0;34m[0m[0;34m[0m[0m

[0;32m~/opt/anaconda3/lib/python3.9/site-packages/nasdaqdatalink/connection.py[0m in [0;36mexecute_request[0;34m(cls, http_verb, url, **options)[0m
[1;32m     49[0m                                        **options)
[1;32m     50[0m             [0;32mif[0m [0mresponse[0m[0;34m.[0m[0mstatus_code[0m [0;34m<[0m [0;36m200[0m [0;32mor[0m [0mresponse[0m[0;34m.[0m[0mstatus_code[0m [0;34m>=[0m [0;36m300[0m[0;34m:[0m[0;34m[0m[0;34m[0m[0m
[0;32m---> 51[0;31m                 [0mcls[0m[0;34m.[0m[0mhandle_api_error[0m[0;34m([0m[0mresponse[0m[0;34m)[0m[0;34m[0m[0;34m[0m[0m
[0m[1;32m     52[0m             [0;32melse[0m[0;34m:[0m[0;34m[0m[0;34m[0m[0m
[1;32m     53[0m                 [0;32mreturn[0m [0mresponse[0m[0;34m[0m[0;34m[0m[0m

[0;32m~/opt/anaconda3/lib/python3.9/site-packages/nasdaqdatalink/connection.py[0m in [0;36mhandle_api_error[0;34m(cls, resp)[0m
[1;32m     94[0m         [0;31m# throw generic error[0m[0;34m[0m[0;34m[0m[0m
[1;32m     95[0m         [0;32mif[0m [0;34m'error'[0m [0;32mnot[0m [0;32min[0m [0merror_body[0m[0;34m:[0m[0;34m[0m[0;34m[0m[0m
[0;32m---> 96[0;31m             [0;32mraise[0m [0mDataLinkError[0m[0;34m([0m[0mhttp_status[0m[0;34m=[0m[0mresp[0m[0;34m.[0m[0mstatus_code[0m[0;34m,[0m [0mhttp_body[0m[0;34m=[0m[0mresp[0m[0;34m.[0m[0mtext[0m[0;34m)[0m[0;34m[0m[0;34m[0m[0m
[0m[1;32m     97[0m [0;34m[0m[0m
[1;32m     98[0m         [0mcode[0m [0;34m=[0m [0merror_body[0m[0;34m[[0m[0;34m'error'[0m[0;34m][0m[0;34m[[0m[0;34m'code'[0m[0;34m][0m[0;34m[0m[0;34m[0m[0m

[0;31mDataLinkError[0m: (Status 429) Something went wrong. Please try again. If you continue to have problems, please contact us at connect@data.nasdaq.com.
DataLinkError: (Status 429) Something went wrong. Please try again. If you continue to have problems, please contact us at connect@data.nasdaq.com.

