Traceback (most recent call last):
  File "/Users/adamaiken/opt/anaconda3/lib/python3.9/site-packages/jupyter_cache/executors/utils.py", line 51, in single_nb_execution
    executenb(
  File "/Users/adamaiken/opt/anaconda3/lib/python3.9/site-packages/nbclient/client.py", line 1112, in execute
    return NotebookClient(nb=nb, resources=resources, km=km, **kwargs).execute()
  File "/Users/adamaiken/opt/anaconda3/lib/python3.9/site-packages/nbclient/util.py", line 74, in wrapped
    return just_run(coro(*args, **kwargs))
  File "/Users/adamaiken/opt/anaconda3/lib/python3.9/site-packages/nbclient/util.py", line 53, in just_run
    return loop.run_until_complete(coro)
  File "/Users/adamaiken/opt/anaconda3/lib/python3.9/asyncio/base_events.py", line 642, in run_until_complete
    return future.result()
  File "/Users/adamaiken/opt/anaconda3/lib/python3.9/site-packages/nbclient/client.py", line 553, in async_execute
    await self.async_execute_cell(
  File "/Users/adamaiken/opt/anaconda3/lib/python3.9/site-packages/nbclient/client.py", line 857, in async_execute_cell
    self._check_raise_for_error(cell, exec_reply)
  File "/Users/adamaiken/opt/anaconda3/lib/python3.9/site-packages/nbclient/client.py", line 760, in _check_raise_for_error
    raise CellExecutionError.from_cell_and_msg(cell, exec_reply_content)
nbclient.exceptions.CellExecutionError: An error occurred while executing the following cell:
------------------
rets.cumsum().apply(np.exp).resample('1m', label='right').last(
                          ).plot(figsize=(10, 6));  
------------------

[0;31m---------------------------------------------------------------------------[0m
[0;31mNameError[0m                                 Traceback (most recent call last)
[0;32m/var/folders/sm/f4lq92s11392x68kwf0scq3w0000gn/T/ipykernel_27753/3404713906.py[0m in [0;36m<module>[0;34m[0m
[0;32m----> 1[0;31m rets.cumsum().apply(np.exp).resample('1m', label='right').last(
[0m[1;32m      2[0m                           ).plot(figsize=(10, 6));  

[0;31mNameError[0m: name 'rets' is not defined
NameError: name 'rets' is not defined

